<?xml version="1.0" ?>
<!-- =================================================================================== -->
<!-- |    This document was autogenerated by xacro from franka_ros/franka_description/robots/panda/panda.urdf.xacro | -->
<!-- |    EDITING THIS FILE BY HAND IS NOT RECOMMENDED                                 | -->
<!-- =================================================================================== -->
<robot name="panda" xmlns:xacro="http://www.ros.org/wiki/xacro">
    <link name="world"/>
    <joint name="world_to_arm" type="fixed">
        <parent link="world"/>
        <child link="panda_link0"/>
        <origin rpy="-1.5707963267948966 0 0" xyz="0 0 0"/>
    </joint>

    <link name="panda_link0">
        <visual>
            <geometry>
                <mesh filename="meshes/visual/link0.obj" />
            </geometry>
        </visual>
        <collision>
            <geometry>
                <mesh filename="meshes/collision/link0.obj" />
            </geometry>
        </collision>
        <inertial>
            <origin rpy="0 0 0" xyz="-0.041018 -0.00014 0.049974"/>
            <mass value="0.629769"/>
            <inertia ixx="0.00315" ixy="8.2904e-07" ixz="0.00015" iyy="0.00388" iyz="8.2299e-06" izz="0.004285"/>
        </inertial>
    </link>
    <link name="panda_link1">
        <visual>
            <geometry>
                <mesh filename="meshes/visual/link1.obj" />
            </geometry>
        </visual>
        <collision>
            <geometry>
                <mesh filename="meshes/collision/link1.obj" />
            </geometry>
        </collision>
        <inertial>
            <origin rpy="0 0 0" xyz="0.003875 0.002081 -0.04762"/>
            <mass value="4.970684"/>
            <inertia ixx="0.70337" ixy="-0.000139" ixz="0.006772" iyy="0.70661" iyz="0.019169" izz="0.009117"/>
        </inertial>
    </link>
    <joint name="panda_joint1" type="revolute">
        <origin rpy="0 0 0" xyz="0 0 0.333"/>
        <parent link="panda_link0"/>
        <child link="panda_link1"/>
        <axis xyz="0 0 1"/>
        <limit effort="87.0" lower="-2.8973" upper="2.8973" velocity="2.175"/>
        <safety_controller k_position="100.0" k_velocity="40.0" soft_lower_limit="-2.8973" soft_upper_limit="2.8973"/>
        <dynamics D="1" K="7000" damping="0.003" friction="0.0" mu_coulomb="0" mu_viscous="16"/>
    </joint>
    <link name="panda_link2">
        <visual>
            <geometry>
                <mesh filename="meshes/visual/link2.obj" />
            </geometry>
        </visual>
        <collision>
            <geometry>
                <mesh filename="meshes/collision/link2.obj" />
            </geometry>
        </collision>
        <inertial>
            <origin rpy="0 0 0" xyz="-0.003141 -0.02872  0.003495"/>
            <mass value="0.646926"/>
            <inertia ixx="0.007962" ixy="-0.003925" ixz="0.010254" iyy="0.02811" iyz="0.000704" izz="0.025995"/>
        </inertial>
    </link>
    <joint name="panda_joint2" type="revolute">
        <origin rpy="-1.5707963267948966 0 0" xyz="0 0 0"/>
        <parent link="panda_link1"/>
        <child link="panda_link2"/>
        <axis xyz="0 0 1"/>
        <limit effort="87.0" lower="-1.7628" upper="1.7628" velocity="2.175"/>
        <safety_controller k_position="100.0" k_velocity="40.0" soft_lower_limit="-1.7628" soft_upper_limit="1.7628"/>
        <dynamics D="1" K="7000" damping="0.003" friction="0.0" mu_coulomb="0" mu_viscous="16"/>
    </joint>
    <link name="panda_link3">
        <visual>
            <geometry>
                <mesh filename="meshes/visual/link3.obj" />
            </geometry>
        </visual>
        <collision>
            <geometry>
                <mesh filename="meshes/collision/link3.obj" />
            </geometry>
        </collision>
        <inertial>
            <origin rpy="0 0 0" xyz="2.7518e-02 3.9252e-02 -6.6502e-02"/>
            <mass value="3.228604"/>
            <inertia ixx="0.037242" ixy="-0.004761" ixz="-0.011396" iyy="0.036155" iyz="-0.012805" izz="0.01083"/>
        </inertial>
    </link>
    <joint name="panda_joint3" type="revolute">
        <origin rpy="1.5707963267948966 0 0" xyz="0 -0.316 0"/>
        <parent link="panda_link2"/>
        <child link="panda_link3"/>
        <axis xyz="0 0 1"/>
        <limit effort="87.0" lower="-2.8973" upper="2.8973" velocity="2.175"/>
        <safety_controller k_position="100.0" k_velocity="40.0" soft_lower_limit="-2.8973" soft_upper_limit="2.8973"/>
        <dynamics D="1" K="7000" damping="0.003" friction="0.0" mu_coulomb="0" mu_viscous="16"/>
    </joint>
    <link name="panda_link4">
        <visual>
            <geometry>
                <mesh filename="meshes/visual/link4.obj"/>
            </geometry>
        </visual>
        <collision>
            <geometry>
                <mesh filename="meshes/collision/link4.obj"/>
            </geometry>
        </collision>
        <inertial>
            <origin rpy="0 0 0" xyz="-5.317e-02 1.04419e-01 2.7454e-02"/>
            <mass value="3.587895"/>
            <inertia ixx="0.025853" ixy="0.007796" ixz="-0.001332" iyy="0.019552" iyz="0.008641" izz="0.028323"/>
        </inertial>
    </link>
    <joint name="panda_joint4" type="revolute">
        <origin rpy="1.5707963267948966 0 0" xyz="0.0825 0 0"/>
        <parent link="panda_link3"/>
        <child link="panda_link4"/>
        <axis xyz="0 0 1"/>
        <limit effort="87.0" lower="-3.0718" upper="-0.0698" velocity="2.175"/>
        <safety_controller k_position="100.0" k_velocity="40.0" soft_lower_limit="-3.0718" soft_upper_limit="-0.0698"/>
        <dynamics D="1" K="7000" damping="0.003" friction="0.0" mu_coulomb="0" mu_viscous="16"/>
    </joint>
    <link name="panda_link5">
        <visual>
            <geometry>
                <mesh filename="meshes/visual/link5.obj" />
            </geometry>
        </visual>
        <collision>
            <geometry>
                <mesh filename="meshes/collision/link5.obj" />
            </geometry>
        </collision>
        <inertial>
            <origin rpy="0 0 0" xyz="-1.1953e-02 4.1065e-02 -3.8437e-02"/>
            <mass value="1.225946"/>
            <inertia ixx="0.035549" ixy="-0.002117" ixz="-0.004037" iyy="0.029474" iyz="0.000229" izz="0.008627"/>
        </inertial>
    </link>
    <joint name="panda_joint5" type="revolute">
        <origin rpy="-1.5707963267948966 0 0" xyz="-0.0825 0.384 0"/>
        <parent link="panda_link4"/>
        <child link="panda_link5"/>
        <axis xyz="0 0 1"/>
        <limit effort="12.0" lower="-2.8973" upper="2.8973" velocity="2.61"/>
        <safety_controller k_position="100.0" k_velocity="40.0" soft_lower_limit="-2.8973" soft_upper_limit="2.8973"/>
        <dynamics D="1" K="7000" damping="0.003" friction="0.0" mu_coulomb="0" mu_viscous="16"/>
    </joint>
    <link name="panda_link6">
        <visual>
            <geometry>
                <mesh filename="meshes/visual/link6.obj" />
            </geometry>
        </visual>
        <collision>
            <geometry>
                <mesh filename="meshes/collision/link6.obj" />
            </geometry>
        </collision>
        <inertial>
            <origin rpy="0 0 0" xyz="6.0149e-02 -1.4117e-02 -1.0517e-02"/>
            <mass value="1.666555"/>
            <inertia ixx="0.001964" ixy="0.000109" ixz="-0.001158" iyy="0.004354" iyz="0.000341" izz="0.005433"/>
        </inertial>
    </link>
    <joint name="panda_joint6" type="revolute">
        <origin rpy="1.5707963267948966 0 0" xyz="0 0 0"/>
        <parent link="panda_link5"/>
        <child link="panda_link6"/>
        <axis xyz="0 0 1"/>
        <limit effort="12.0" lower="-0.0175" upper="3.7525" velocity="2.61"/>
        <safety_controller k_position="100.0" k_velocity="40.0" soft_lower_limit="-0.0175" soft_upper_limit="3.7525"/>
        <dynamics D="1" K="7000" damping="0.003" friction="0.0" mu_coulomb="0" mu_viscous="16"/>
    </joint>
    <link name="panda_link7">
        <visual>
            <geometry>
                <mesh filename="meshes/visual/link7.obj" />
            </geometry>
        </visual>
        <collision>
            <geometry>
                <mesh filename="meshes/collision/link7.obj" />
            </geometry>
        </collision>
        <inertial>
            <origin rpy="0 0 0" xyz="1.0517e-02 -4.252e-03 6.1597e-02"/>
            <mass value="0.735522"/>
            <inertia ixx="0.012516" ixy="-0.000428" ixz="-0.001196" iyy="0.010027" iyz="-0.000741" izz="0.004815"/>
        </inertial>
    </link>
    <joint name="panda_joint7" type="revolute">
        <origin rpy="1.5707963267948966 0 0" xyz="0.088 0 0"/>
        <parent link="panda_link6"/>
        <child link="panda_link7"/>
        <axis xyz="0 0 1"/>
        <limit effort="12.0" lower="-2.8973" upper="2.8973" velocity="2.61"/>
        <safety_controller k_position="100.0" k_velocity="40.0" soft_lower_limit="-2.8973" soft_upper_limit="2.8973"/>
        <dynamics D="1" K="7000" damping="0.003" friction="0.0" mu_coulomb="0" mu_viscous="16"/>
    </joint>
    <link name="panda_link8">
        <inertial>
          <mass value="0"/>
          <origin rpy="0 0 0" xyz="0 0 0"/>
          <inertia ixx="0" ixy="0" ixz="0" iyy="0" iyz="0" izz="0"/>
        </inertial>
    </link>
    <joint name="panda_joint8" type="fixed">
        <origin rpy="0 0 0" xyz="0 0 0.107"/>
        <parent link="panda_link7"/>
        <child link="panda_link8"/>
    </joint>

</robot>
